Workbook

Sheet Public land
C1: 1863 | L1: 1864 | U1: 1865 | AD1: 1866 | AM1: 1867 | AV1: 1868 | BE1: 1869 | BN1: 1870 | BW1: 1871 | CF1: 1872 | CO1: 1873 | CX1: 1874 | DG1: 1875 | DP1: 1876 | DY1: 1877 | EH1: 1878 | EQ1: 1879 | EZ1: 1880 | FI1: 1881 | FR1: 1882 | GA1: 1883 | GJ1: 1884 | GS1: 1885 | HB1: 1886 | HK1: 1887 | HT1: 1888 | IC1: 1889 | IL1: 1890 | IU1: 1891 | JD1: 1892 | JM1: 1893 | JV1: 1894 | KE1: 1895 | KN1: 1896 | KW1: 1897 | LF1: 1898 | LO1: 1899 | LX1: 1900 | MG1: 1901 | MP1: 1902 | MY1: 1903 | NH1: 1904 | NQ1: 1905 | NZ1: 1906 | OI1: 1907 | OR1: 1908 | PA1: 1909 | PJ1: 1910 | PS1: 1911 | QB1: 1912
A2: land office | B2: state | C2: claims (no.) | D2: claims (acres) | E2: patents (no.) | F2: patents (acres) | G2: commutations sec 2301 (no.) | H2: commutations sec 2301 (acres) | I2: commutations june 15, 1880 (no.) | J2: commutations june 15, 1880 (acres) | K2: commutations sec 2301 ($) | L2: claims (no.) | M2: claims (acres) | N2: patents (no.) | O2: patents (acres) | P2: commutations sec 2301 (no.) | Q2: commutations sec 2301 (acres) | R2: commutations june 15, 1880 (no.) | S2: commutations june 15, 1880 (acres) | T2: commutations sec 2301 ($) | U2: claims (no.) | V2: claims (acres) | W2: patents (no.) | X2: patents (acres) | Y2: commutations sec 2301 (no.) | Z2: commutations sec 2301 (acres) | AA2: commutations june 15, 1880 (no.) | AB2: commutations june 15, 1880 (acres) | AC2: commutations sec 2301 ($) | AD2: claims (no.) | AE2: claims (acres) | AF2: patents (no.) | AG2: patents (acres) | AH2: commutations sec 2301 (no.) | AI2: commutations sec 2301 (acres) | AJ2: commutations june 15, 1880 (no.) | AK2: commutations june 15, 1880 (acres) | AL2: commutations sec 2301 ($) | AM2: claims (no.) | AN2: claims (acres) | AO2: patents (no.) | AP2: patents (acres) | AQ2: commutations sec 2301 (no.) | AR2: commutations sec 2301 (acres) | AS2: commutations june 15, 1880 (no.) | AT2: commutations june 15, 1880 (acres) | AU2: commutations sec 2301 ($) | AV2: claims (no.) | AW2: claims (acres) | AX2: patents (no.) | AY2: patents (acres) | AZ2: commutations sec 2301 (no.) | BA2: commutations sec 2301 (acres) | BB2: commutations june 15, 1880 (no.) | BC2: commutations june 15, 1880 (acres) | BD2: commutations sec 2301 ($) | BE2: claims (no.) | BF2: claims (acres) | BG2: patents (no.) | BH2: patents (acres) | BI2: commutations sec 2301 (no.) | BJ2: commutations sec 2301 (acres) | BK2: commutations june 15, 1880 (no.) | BL2: commutations june 15, 1880 (acres) | BM2: commutations sec 2301 ($) | BN2: claims (no.) | BO2: claims (acres) | BP2: patents (no.) | BQ2: patents (acres) | BR2: commutations sec 2301 (no.) | BS2: commutations sec 2301 (acres) | BT2: commutations june 15, 1880 (no.) | BU2: commutations june 15, 1880 (acres) | BV2: commutations sec 2301 ($) | BW2: claims (no.) | BX2: claims (acres) | BY2: patents (no.) | BZ2: patents (acres) | CA2: commutations sec 2301 (no.) | CB2: commutations sec 2301 (acres) | CC2: commutations june 15, 1880 (no.) | CD2: commutations june 15, 1880 (acres) | CE2: commutations sec 2301 ($) | CF2: claims (no.) | CG2: claims (acres) | CH2: patents (no.) | CI2: patents (acres) | CJ2: commutations sec 2301 (no.) | CK2: commutations sec 2301 (acres) | CL2: commutations june 15, 1880 (no.) | CM2: commutations june 15, 1880 (acres) | CN2: commutations sec 2301 ($) | CO2: claims (no.) | CP2: claims (acres) | CQ2: patents (no.) | CR2: patents (acres) | CS2: commutations sec 2301 (no.) | CT2: commutations sec 2301 (acres) | CU2: commutations june 15, 1880 (no.) | CV2: commutations june 15, 1880 (acres) | CW2: commutations sec 2301 ($) | CX2: claims (no.) | CY2: claims (acres) | CZ2: patents (no.) | DA2: patents (acres) | DB2: commutations sec 2301 (no.) | DC2: commutations sec 2301 (acres) | DD2: commutations june 15, 1880 (no.) | DE2: commutations june 15, 1880 (acres) | DF2: commutations sec 2301 ($) | DG2: claims (no.) | DH2: claims (acres) | DI2: patents (no.) | DJ2: patents (acres) | DK2: commutations sec 2301 (no.) | DL2: commutations sec 2301 (acres) | DM2: commutations june 15, 1880 (no.) | DN2: commutations june 15, 1880 (acres) | DO2: commutations sec 2301 ($) | DP2: claims (no.) | DQ2: claims (acres) | DR2: patents (no.) | DS2: patents (acres) | DT2: commutations sec 2301 (no.) | DU2: commutations sec 2301 (acres) | DV2: commutations june 15, 1880 (no.) | DW2: commutations june 15, 1880 (acres) | DX2: commutations sec 2301 ($) | DY2: claims (no.) | DZ2: claims (acres) | EA2: patents (no.) | EB2: patents (acres) | EC2: commutations sec 2301 (no.) | ED2: commutations sec 2301 (acres) | EE2: commutations june 15, 1880 (no.) | EF2: commutations june 15, 1880 (acres) | EG2: commutations sec 2301 ($) | EH2: claims (no.) | EI2: claims (acres) | EJ2: patents (no.) | EK2: patents (acres) | EL2: commutations sec 2301 (no.) | EM2: commutations sec 2301 (acres) | EN2: commutations june 15, 1880 (no.) | EO2: commutations june 15, 1880 (acres) | EP2: commutations sec 2301 ($) | EQ2: claims (no.) | ER2: claims (acres) | ES2: patents (no.) | ET2: patents (acres) | EU2: commutations sec 2301 (no.) | EV2: commutations sec 2301 (acres) | EW2: commutations june 15, 1880 (no.) | EX2: commutations june 15, 1880 (acres) | EY2: commutations sec 2301 ($) | EZ2: claims (no.) | FA2: claims (acres) | FB2: patents (no.) | FC2: patents (acres) | FD2: commutations sec 2301 (no.) | FE2: commutations sec 2301 (acres) | FF2: commutations june 15, 1880 (no.) | FG2: commutations june 15, 1880 (acres) | FH2: commutations sec 2301 ($) | FI2: claims (no.) | FJ2: claims (acres) | FK2: patents (no.) | FL2: patents (acres) | FM2: commutations sec 2301 (no.) | FN2: commutations sec 2301 (acres) | FO2: commutations june 15, 1880 (no.) | FP2: commutations june 15, 1880 (acres) | FQ2: commutations sec 2301 ($) | FR2: claims (no.) | FS2: claims (acres) | FT2: patents (no.) | FU2: patents (acres) | FV2: commutations sec 2301 (no.) | FW2: commutations sec 2301 (acres) | FX2: commutations june 15, 1880 (no.) | FY2: commutations june 15, 1880 (acres) | FZ2: commutations sec 2301 ($) | GA2: claims (no.) | GB2: claims (acres) | GC2: patents (no.) | GD2: patents (acres) | GE2: commutations sec 2301 (no.) | GF2: commutations sec 2301 (acres) | GG2: commutations june 15, 1880 (no.) | GH2: commutations june 15, 1880 (acres) | GI2: commutations sec 2301 ($) | GJ2: claims (no.) | GK2: claims (acres) | GL2: patents (no.) | GM2: patents (acres) | GN2: commutations sec 2301 (no.) | GO2: commutations sec 2301 (acres) | GP2: commutations june 15, 1880 (no.) | GQ2: commutations june 15, 1880 (acres) | GR2: commutations sec 2301 ($) | GS2: claims (no.) | GT2: claims (acres) | GU2: patents (no.) | GV2: patents (acres) | GW2: commutations sec 2301 (no.) | GX2: commutations sec 2301 (acres) | GY2: commutations june 15, 1880 (no.) | GZ2: commutations june 15, 1880 (acres) | HA2: commutations sec 2301 ($) | HB2: claims (no.) | HC2: claims (acres) | HD2: patents (no.) | HE2: patents (acres) | HF2: commutations sec 2301 (no.) | HG2: commutations sec 2301 (acres) | HH2: commutations june 15, 1880 (no.) | HI2: commutations june 15, 1880 (acres) | HJ2: commutations sec 2301 ($) | HK2: claims (no.) | HL2: claims (acres) | HM2: patents (no.) | HN2: patents (acres) | HO2: commutations sec 2301 (no.) | HP2: commutations sec 2301 (acres) | HQ2: commutations june 15, 1880 (no.) | HR2: commutations june 15, 1880 (acres) | HS2: commutations sec 2301 ($) | HT2: claims (no.) | HU2: claims (acres) | HV2: patents (no.) | HW2: patents (acres) | HX2: commutations sec 2301 (no.) | HY2: commutations sec 2301 (acres) | HZ2: commutations june 15, 1880 (no.) | IA2: commutations june 15, 1880 (acres) | IB2: commutations sec 2301 ($) | IC2: claims (no.) | ID2: claims (acres) | IE2: patents (no.) | IF2: patents (acres) | IG2: commutations sec 2301 (no.) | IH2: commutations sec 2301 (acres) | II2: commutations june 15, 1880 (no.) | IJ2: commutations june 15, 1880 (acres) | IK2: commutations sec 2301 ($) | IL2: claims (no.) | IM2: claims (acres) | IN2: patents (no.) | IO2: patents (acres) | IP2: commutations sec 2301 (no.) | IQ2: commutations sec 2301 (acres) | IR2: commutations june 15, 1880 (no.) | IS2: commutations june 15, 1880 (acres) | IT2: commutations sec 2301 ($) | IU2: claims (no.) | IV2: claims (acres) | IW2: patents (no.) | IX2: patents (acres) | IY2: commutations sec 2301 (no.) | IZ2: commutations sec 2301 (acres) | JA2: commutations june 15, 1880 (no.) | JB2: commutations june 15, 1880 (acres) | JC2: commutations sec 2301 ($) | JD2: claims (no.) | JE2: claims (acres) | JF2: patents (no.) | JG2: patents (acres) | JH2: commutations sec 2301 (no.) | JI2: commutations sec 2301 (acres) | JJ2: commutations june 15, 1880 (no.) | JK2: commutations june 15, 1880 (acres) | JL2: commutations sec 2301 ($) | JM2: claims (no.) | JN2: claims (acres) | JO2: patents (no.) | JP2: patents (acres) | JQ2: commutations sec 2301 (no.) | JR2: commutations sec 2301 (acres) | JS2: commutations june 15, 1880 (no.) | JT2: commutations june 15, 1880 (acres) | JU2: commutations sec 2301 ($) | JV2: claims (no.) | JW2: claims (acres) | JX2: patents (no.) | JY2: patents (acres) | JZ2: commutations sec 2301 (no.) | KA2: commutations sec 2301 (acres) | KB2: commutations june 15, 1880 (no.) | KC2: commutations june 15, 1880 (acres) | KD2: commutations sec 2301 ($) | KE2: claims (no.) | KF2: claims (acres) | KG2: patents (no.) | KH2: patents (acres) | KI2: commutations sec 2301 (no.) | KJ2: commutations sec 2301 (acres) | KK2: commutations june 15, 1880 (no.) | KL2: commutations june 15, 1880 (acres) | KM2: commutations sec 2301 ($) | KN2: claims (no.) | KO2: claims (acres) | KP2: patents (no.) | KQ2: patents (acres) | KR2: commutations sec 2301 (no.) | KS2: commutations sec 2301 (acres) | KT2: commutations june 15, 1880 (no.) | KU2: commutations june 15, 1880 (acres) | KV2: commutations sec 2301 ($) | KW2: claims (no.) | KX2: claims (acres) | KY2: patents (no.) | KZ2: patents (acres) | LA2: commutations sec 2301 (no.) | LB2: commutations sec 2301 (acres) | LC2: commutations june 15, 1880 (no.) | LD2: commutations june 15, 1880 (acres) | LE2: commutations sec 2301 ($) | LF2: claims (no.) | LG2: claims (acres) | LH2: patents (no.) | LI2: patents (acres) | LJ2: commutations sec 2301 (no.) | LK2: commutations sec 2301 (acres) | LL2: commutations june 15, 1880 (no.) | LM2: commutations june 15, 1880 (acres) | LN2: commutations sec 2301 ($) | LO2: claims (no.) | LP2: claims (acres) | LQ2: patents (no.) | LR2: patents (acres) | LS2: commutations sec 2301 (no.) | LT2: commutations sec 2301 (acres) | LU2: commutations june 15, 1880 (no.) | LV2: commutations june 15, 1880 (acres) | LW2: commutations sec 2301 ($) | LX2: claims (no.) | LY2: claims (acres) | LZ2: patents (no.) | MA2: patents (acres) | MB2: commutations sec 2301 (no.) | MC2: commutations sec 2301 (acres) | MD2: commutations june 15, 1880 (no.) | ME2: commutations june 15, 1880 (acres) | MF2: commutations sec 2301 ($) | MG2: claims (no.) | MH2: claims (acres) | MI2: patents (no.) | MJ2: patents (acres) | MK2: commutations sec 2301 (no.) | ML2: commutations sec 2301 (acres) | MM2: commutations june 15, 1880 (no.) | MN2: commutations june 15, 1880 (acres) | MO2: commutations sec 2301 ($) | MP2: claims (no.) | MQ2: claims (acres) | MR2: patents (no.) | MS2: patents (acres) | MT2: commutations sec 2301 (no.) | MU2: commutations sec 2301 (acres) | MV2: commutations june 15, 1880 (no.) | MW2: commutations june 15, 1880 (acres) | MX2: commutations sec 2301 ($) | MY2: claims (no.) | MZ2: claims (acres) | NA2: patents (no.) | NB2: patents (acres) | NC2: commutations sec 2301 (no.) | ND2: commutations sec 2301 (acres) | NE2: commutations june 15, 1880 (no.) | NF2: commutations june 15, 1880 (acres) | NG2: commutations sec 2301 ($) | NH2: claims (no.) | NI2: claims (acres) | NJ2: patents (no.) | NK2: patents (acres) | NL2: commutations sec 2301 (no.) | NM2: commutations sec 2301 (acres) | NN2: commutations june 15, 1880 (no.) | NO2: commutations june 15, 1880 (acres) | NP2: commutations sec 2301 ($) | NQ2: claims (no.) | NR2: claims (acres) | NS2: patents (no.) | NT2: patents (acres) | NU2: commutations sec 2301 (no.) | NV2: commutations sec 2301 (acres) | NW2: commutations june 15, 1880 (no.) | NX2: commutations june 15, 1880 (acres) | NY2: commutations sec 2301 ($) | NZ2: claims (no.) | OA2: claims (acres) | OB2: patents (no.) | OC2: patents (acres) | OD2: commutations sec 2301 (no.) | OE2: commutations sec 2301 (acres) | OF2: commutations june 15, 1880 (no.) | OG2: commutations june 15, 1880 (acres) | OH2: commutations sec 2301 ($) | OI2: claims (no.) | OJ2: claims (acres) | OK2: patents (no.) | OL2: patents (acres) | OM2: commutations sec 2301 (no.) | ON2: commutations sec 2301 (acres) | OO2: commutations june 15, 1880 (no.) | OP2: commutations june 15, 1880 (acres) | OQ2: commutations sec 2301 ($) | OR2: claims (no.) | OS2: claims (acres) | OT2: patents (no.) | OU2: patents (acres) | OV2: commutations sec 2301 (no.) | OW2: commutations sec 2301 (acres) | OX2: commutations june 15, 1880 (no.) | OY2: commutations june 15, 1880 (acres) | OZ2: commutations sec 2301 ($) | PA2: claims (no.) | PB2: claims (acres) | PC2: patents (no.) | PD2: patents (acres) | PE2: commutations sec 2301 (no.) | PF2: commutations sec 2301 (acres) | PG2: commutations june 15, 1880 (no.) | PH2: commutations june 15, 1880 (acres) | PI2: commutations sec 2301 ($) | PJ2: claims (no.) | PK2: claims (acres) | PL2: patents (no.) | PM2: patents (acres) | PN2: commutations sec 2301 (no.) | PO2: commutations sec 2301 (acres) | PP2: commutations june 15, 1880 (no.) | PQ2: commutations june 15, 1880 (acres) | PR2: commutations sec 2301 ($) | PS2: claims (no.) | PT2: claims (acres) | PU2: patents (no.) | PV2: patents (acres) | PW2: commutations sec 2301 (no.) | PX2: commutations sec 2301 (acres) | PY2: commutations june 15, 1880 (no.) | PZ2: commutations june 15, 1880 (acres) | QA2: commutations sec 2301 ($) | QB2: claims (no.) | QC2: claims (acres) | QD2: patents (no.) | QE2: patents (acres) | QF2: commutations sec 2301 (no.) | QG2: commutations sec 2301 (acres) | QH2: commutations june 15, 1880 (no.) | QI2: commutations june 15, 1880 (acres) | QJ2: commutations sec 2301 ($)
A3: Huntsville, AL | B3: Alabama | C3: =IFERROR(VLOOKUP($A3,'1863'!$A$3:$B$140,2,FALSE),"") | D3: =IFERROR(VLOOKUP($A3,'1863'!$A$3:$C$140,3,FALSE),"") | E3: =IFERROR(VLOOKUP($A3,'1863'!$A$3:$D$140,4,FALSE),"") | F3: =IFERROR(VLOOKUP($A3,'1863'!$A$3:$E$140,5,FALSE),"") | G3: =IFERROR(VLOOKUP($A3,'1863'!$A$3:$F$140,6,FALSE),"") | H3: =IFERROR(VLOOKUP($A3,'1863'!$A$3:$G$140,7,FALSE),"") | I3: =IFERROR(VLOOKUP($A3,'1863'!$A$3:$H$140,8,FALSE),"") | J3: =IFERROR(VLOOKUP($A3,'1863'!$A$3:$I$140,9,FALSE),"") | K3: =IFERROR(VLOOKUP($A3,'1863'!$A$3:$J$140,10,FALSE),"") | L3: =IFERROR(VLOOKUP($A3,'1864'!$A$3:$B$140,2,FALSE),"") | M3: =IFERROR(VLOOKUP($A3,'1864'!$A$3:$C$140,3,FALSE),"") | N3: =IFERROR(VLOOKUP($A3,'1864'!$A$3:$D$140,4,FALSE),"") | O3: =IFERROR(VLOOKUP($A3,'1864'!$A$3:$E$140,5,FALSE),"") | P3: =IFERROR(VLOOKUP($A3,'1864'!$A$3:$F$140,6,FALSE),"") | Q3: =IFERROR(VLOOKUP($A3,'1864'!$A$3:$G$140,7,FALSE),"") | R3: =IFERROR(VLOOKUP($A3,'1864'!$A$3:$H$140,8,FALSE),"") | S3: =IFERROR(VLOOKUP($A3,'1864'!$A$3:$I$140,9,FALSE),"") | T3: =IFERROR(VLOOKUP($A3,'1864'!$A$3:$J$140,10,FALSE),"") | U3: =IFERROR(VLOOKUP($A3,'1865'!$A$3:$B$140,2,FALSE),"") | V3: =IFERROR(VLOOKUP($A3,'1865'!$A$3:$C$140,3,FALSE),"") | W3: =IFERROR(VLOOKUP($A3,'1865'!$A$3:$D$140,4,FALSE),"") | X3: =IFERROR(VLOOKUP($A3,'1865'!$A$3:$E$140,5,FALSE),"") | Y3: =IFERROR(VLOOKUP($A3,'1865'!$A$3:$F$140,6,FALSE),"") | Z3: =IFERROR(VLOOKUP($A3,'1865'!$A$3:$G$140,7,FALSE),"") | AA3: =IFERROR(VLOOKUP($A3,'1865'!$A$3:$H$140,8,FALSE),"") | AB3: =IFERROR(VLOOKUP($A3,'1865'!$A$3:$I$140,9,FALSE),"") | AC3: =IFERROR(VLOOKUP($A3,'1865'!$A$3:$J$140,10,FALSE),"") | AD3: =IFERROR(VLOOKUP($A3,'1866'!$A$3:$B$140,2,FALSE),"") | AE3: =IFERROR(VLOOKUP($A3,'1866'!$A$3:$C$140,3,FALSE),"") | AF3: =IFERROR(VLOOKUP($A3,'1866'!$A$3:$D$140,4,FALSE),"") | AG3: =IFERROR(VLOOKUP($A3,'1866'!$A$3:$E$140,5,FALSE),"") | AH3: =IFERROR(VLOOKUP($A3,'1866'!$A$3:$F$140,6,FALSE),"") | AI3: =IFERROR(VLOOKUP($A3,'1866'!$A$3:$G$140,7,FALSE),"") | AJ3: =IFERROR(VLOOKUP($A3,'1866'!$A$3:$H$140,8,FALSE),"") | AK3: =IFERROR(VLOOKUP($A3,'1866'!$A$3:$I$140,9,FALSE),"") | AL3: =IFERROR(VLOOKUP($A3,'1866'!$A$3:$J$140,10,FALSE),"") | AM3: =IFERROR(VLOOKUP($A3,'1867'!$A$3:$B$140,2,FALSE),"") -> 569 | AN3: =IFERROR(VLOOKUP($A3,'1867'!$A$3:$C$140,3,FALSE),"") -> 43808.17 | AO3: =IFERROR(VLOOKUP($A3,'1867'!$A$3:$D$140,4,FALSE),"") -> 0 | AP3: =IFERROR(VLOOKUP($A3,'1867'!$A$3:$E$140,5,FALSE),"") -> 0 | AQ3: =IFERROR(VLOOKUP($A3,'1867'!$A$3:$F$140,6,FALSE),"") -> 0 | AR3: =IFERROR(VLOOKUP($A3,'1867'!$A$3:$G$140,7,FALSE),"") -> 0 | AS3: =IFERROR(VLOOKUP($A3,'1867'!$A$3:$H$140,8,FALSE),"") -> 0 | AT3: =IFERROR(VLOOKUP($A3,'1867'!$A$3:$I$140,9,FALSE),"") -> 0 | AU3: =IFERROR(VLOOKUP($A3,'1867'!$A$3:$J$140,10,FALSE),"") -> 0 | AV3: =IFERROR(VLOOKUP($A3,'1868'!$A$3:$B$140,2,FALSE),"") -> 1646 | AW3: =IFERROR(VLOOKUP($A3,'1868'!$A$3:$C$140,3,FALSE),"") -> 124085.24 | AX3: =IFERROR(VLOOKUP($A3,'1868'!$A$3:$D$140,4,FALSE),"") -> 0 | AY3: =IFERROR(VLOOKUP($A3,'1868'!$A$3:$E$140,5,FALSE),"") -> 0 | AZ3: =IFERROR(VLOOKUP($A3,'1868'!$A$3:$F$140,6,FALSE),"") -> 0 | BA3: =IFERROR(VLOOKUP($A3,'1868'!$A$3:$G$140,7,FALSE),"") -> 0 | BB3: =IFERROR(VLOOKUP($A3,'1868'!$A$3:$H$140,8,FALSE),"") -> 0 | BC3: =IFERROR(VLOOKUP($A3,'1868'!$A$3:$I$140,9,FALSE),"") -> 0 | BD3: =IFERROR(VLOOKUP($A3,'1868'!$A$3:$J$140,10,FALSE),"") -> 0 | BE3: =IFERROR(VLOOKUP($A3,'1869'!$A$3:$B$140,2,FALSE),"") -> 616 | BF3: =IFERROR(VLOOKUP($A3,'1869'!$A$3:$C$140,3,FALSE),"") -> 58357.13 | BG3: =IFERROR(VLOOKUP($A3,'1869'!$A$3:$D$140,4,FALSE),"") -> 0 | BH3: =IFERROR(VLOOKUP($A3,'1869'!$A$3:$E$140,5,FALSE),"") -> 0 | BI3: =IFERROR(VLOOKUP($A3,'1869'!$A$3:$F$140,6,FALSE),"") -> 0 | BJ3: =IFERROR(VLOOKUP($A3,'1869'!$A$3:$G$140,7,FALSE),"") -> 0 | BK3: =IFERROR(VLOOKUP($A3,'1869'!$A$3:$H$140,8,FALSE),"") -> 0 | BL3: =IFERROR(VLOOKUP($A3,'1869'!$A$3:$I$140,9,FALSE),"") -> 0 | BM3: =IFERROR(VLOOKUP($A3,'1869'!$A$3:$J$140,10,FALSE),"") -> 0 | BN3: =IFERROR(VLOOKUP($A3,'1870'!$A$3:$B$140,2,FALSE),"") -> 468 | BO3: =IFERROR(VLOOKUP($A3,'1870'!$A$3:$C$140,3,FALSE),"") -> 44330.35 | BP3: =IFERROR(VLOOKUP($A3,'1870'!$A$3:$D$140,4,FALSE),"") -> 0 | BQ3: =IFERROR(VLOOKUP($A3,'1870'!$A$3:$E$140,5,FALSE),"") -> 0 | BR3: =IFERROR(VLOOKUP($A3,'1870'!$A$3:$F$140,6,FALSE),"") -> 0 | BS3: =IFERROR(VLOOKUP($A3,'1870'!$A$3:$G$140,7,FALSE),"") -> 0 | BT3: =IFERROR(VLOOKUP($A3,'1870'!$A$3:$H$140,8,FALSE),"") -> 0 | BU3: =IFERROR(VLOOKUP($A3,'1870'!$A$3:$I$140,9,FALSE),"") -> 0 | BV3: =IFERROR(VLOOKUP($A3,'1870'!$A$3:$J$140,10,FALSE),"") -> 0 | BW3: =IFERROR(VLOOKUP($A3,'1871'!$A$3:$B$140,2,FALSE),"") -> 358 | BX3: =IFERROR(VLOOKUP($A3,'1871'!$A$3:$C$140,3,FALSE),"") -> 33343.68 | BY3: =IFERROR(VLOOKUP($A3,'1871'!$A$3:$D$140,4,FALSE),"") -> 0 | BZ3: =IFERROR(VLOOKUP($A3,'1871'!$A$3:$E$140,5,FALSE),"") -> 0 | CA3: =IFERROR(VLOOKUP($A3,'1871'!$A$3:$F$140,6,FALSE),"") -> 0 | CB3: =IFERROR(VLOOKUP($A3,'1871'!$A$3:$G$140,7,FALSE),"") -> 0 | CC3: =IFERROR(VLOOKUP($A3,'1871'!$A$3:$H$140,8,FALSE),"") -> 0 | CD3: =IFERROR(VLOOKUP($A3,'1871'!$A$3:$I$140,9,FALSE),"") -> 0 | CE3: =IFERROR(VLOOKUP($A3,'1871'!$A$3:$J$140,10,FALSE),"") -> 599.87 | CF3: =IFERROR(VLOOKUP($A3,'1872'!$A$3:$B$140,2,FALSE),"") -> 432 | CG3: =IFERROR(VLOOKUP($A3,'1872'!$A$3:$C$140,3,FALSE),"") -> 42993.85 | CH3: =IFERROR(VLOOKUP($A3,'1872'!$A$3:$D$140,4,FALSE),"") -> 12 | CI3: =IFERROR(VLOOKUP($A3,'1872'!$A$3:$E$140,5,FALSE),"") -> 966.5 | CJ3: =IFERROR(VLOOKUP($A3,'1872'!$A$3:$F$140,6,FALSE),"") -> 0 | CK3: =IFERROR(VLOOKUP($A3,'1872'!$A$3:$G$140,7,FALSE),"") -> 0 | CL3: =IFERROR(VLOOKUP($A3,'1872'!$A$3:$H$140,8,FALSE),"") -> 0 | CM3: =IFERROR(VLOOKUP($A3,'1872'!$A$3:$I$140,9,FALSE),"") -> 0 | CN3: =IFERROR(VLOOKUP($A3,'1872'!$A$3:$J$140,10,FALSE),"") -> 0 | CO3: =IFERROR(VLOOKUP($A3,'1873'!$A$3:$B$140,2,FALSE),"") -> 696 | CP3: =IFERROR(VLOOKUP($A3,'1873'!$A$3:$C$140,3,FALSE),"") -> 71839.35 | CQ3: =IFERROR(VLOOKUP($A3,'1873'!$A$3:$D$140,4,FALSE),"") -> 55 | CR3: =IFERROR(VLOOKUP($A3,'1873'!$A$3:$E$140,5,FALSE),"") -> 4154.57 | CS3: =IFERROR(VLOOKUP($A3,'1873'!$A$3:$F$140,6,FALSE),"") -> 0 | CT3: =IFERROR(VLOOKUP($A3,'1873'!$A$3:$G$140,7,FALSE),"") -> 0 | CU3: =IFERROR(VLOOKUP($A3,'1873'!$A$3:$H$140,8,FALSE),"") -> 0 | CV3: =IFERROR(VLOOKUP($A3,'1873'!$A$3:$I$140,9,FALSE),"") -> 0 | CW3: =IFERROR(VLOOKUP($A3,'1873'!$A$3:$J$140,10,FALSE),"") -> 300 | CX3: =IFERROR(VLOOKUP($A3,'1874'!$A$3:$B$140,2,FALSE),"") -> 676 | CY3: =IFERROR(VLOOKUP($A3,'1874'!$A$3:$C$140,3,FALSE),"") -> 71929.92 | CZ3: =IFERROR(VLOOKUP($A3,'1874'!$A$3:$D$140,4,FALSE),"") -> 117 | DA3: =IFERROR(VLOOKUP($A3,'1874'!$A$3:$E$140,5,FALSE),"") -> 10053.02 | DB3: =IFERROR(VLOOKUP($A3,'1874'!$A$3:$F$140,6,FALSE),"") -> 0 | DC3: =IFERROR(VLOOKUP($A3,'1874'!$A$3:$G$140,7,FALSE),"") -> 0 | DD3: =IFERROR(VLOOKUP($A3,'1874'!$A$3:$H$140,8,FALSE),"") -> 0 | DE3: =IFERROR(VLOOKUP($A3,'1874'!$A$3:$I$140,9,FALSE),"") -> 0 | DF3: =IFERROR(VLOOKUP($A3,'1874'!$A$3:$J$140,10,FALSE),"") -> 2118.19 | DG3: =IFERROR(VLOOKUP($A3,'1875'!$A$3:$B$140,2,FALSE),"") -> 555 | DH3: =IFERROR(VLOOKUP($A3,'1875'!$A$3:$C$140,3,FALSE),"") -> 57499.97 | DI3: =IFERROR(VLOOKUP($A3,'1875'!$A$3:$D$140,4,FALSE),"") -> 124 | DJ3: =IFERROR(VLOOKUP($A3,'1875'!$A$3:$E$140,5,FALSE),"") -> 11201.1 | DK3: =IFERROR(VLOOKUP($A3,'1875'!$A$3:$F$140,6,FALSE),"") -> 0 | DL3: =IFERROR(VLOOKUP($A3,'1875'!$A$3:$G$140,7,FALSE),"") -> 0 | DM3: =IFERROR(VLOOKUP($A3,'1875'!$A$3:$H$140,8,FALSE),"") -> 0 | DN3: =IFERROR(VLOOKUP($A3,'1875'!$A$3:$I$140,9,FALSE),"") -> 0 | DO3: =IFERROR(VLOOKUP($A3,'1875'!$A$3:$J$140,10,FALSE),"") -> 1245.22 | DP3: =IFERROR(VLOOKUP($A3,'1876'!$A$3:$B$140,2,FALSE),"") -> 735 | DQ3: =IFERROR(VLOOKUP($A3,'1876'!$A$3:$C$140,3,FALSE),"") -> 76051.22 | DR3: =IFERROR(VLOOKUP($A3,'1876'!$A$3:$D$140,4,FALSE),"") -> 198 | DS3: =IFERROR(VLOOKUP($A3,'1876'!$A$3:$E$140,5,FALSE),"") -> 19170.07 | DT3: =IFERROR(VLOOKUP($A3,'1876'!$A$3:$F$140,6,FALSE),"") -> 0 | DU3: =IFERROR(VLOOKUP($A3,'1876'!$A$3:$G$140,7,FALSE),"") -> 0 | DV3: =IFERROR(VLOOKUP($A3,'1876'!$A$3:$H$140,8,FALSE),"") -> 0 | DW3: =IFERROR(VLOOKUP($A3,'1876'!$A$3:$I$140,9,FALSE),"") -> 0 | DX3: =IFERROR(VLOOKUP($A3,'1876'!$A$3:$J$140,10,FALSE),"") -> 699.34 | DY3: =IFERROR(VLOOKUP($A3,'1877'!$A$3:$B$140,2,FALSE),"") -> 686 | DZ3: =IFERROR(VLOOKUP($A3,'1877'!$A$3:$C$140,3,FALSE),"") -> 71554.12 | EA3: =IFERROR(VLOOKUP($A3,'1877'!$A$3:$D$140,4,FALSE),"") -> 181 | EB3: =IFERROR(VLOOKUP($A3,'1877'!$A$3:$E$140,5,FALSE),"") -> 18125.52 | EC3: =IFERROR(VLOOKUP($A3,'1877'!$A$3:$F$140,6,FALSE),"") -> 0 | ED3: =IFERROR(VLOOKUP($A3,'1877'!$A$3:$G$140,7,FALSE),"") -> 0 | EE3: =IFERROR(VLOOKUP($A3,'1877'!$A$3:$H$140,8,FALSE),"") -> 0 | EF3: =IFERROR(VLOOKUP($A3,'1877'!$A$3:$I$140,9,FALSE),"") -> 0 | EG3: =IFERROR(VLOOKUP($A3,'1877'!$A$3:$J$140,10,FALSE),"") -> 846.59 | EH3: =IFERROR(VLOOKUP($A3,'1878'!$A$3:$B$140,2,FALSE),"") -> 1008 | EI3: =IFERROR(VLOOKUP($A3,'1878'!$A$3:$C$140,3,FALSE),"") -> 100031.13 | EJ3: =IFERROR(VLOOKUP($A3,'1878'!$A$3:$D$140,4,FALSE),"") -> 267 | EK3: =IFERROR(VLOOKUP($A3,'1878'!$A$3:$E$140,5,FALSE),"") -> 24498.03 | EL3: =IFERROR(VLOOKUP($A3,'1878'!$A$3:$F$140,6,FALSE),"") -> 0 | EM3: =IFERROR(VLOOKUP($A3,'1878'!$A$3:$G$140,7,FALSE),"") -> 0 | EN3: =IFERROR(VLOOKUP($A3,'1878'!$A$3:$H$140,8,FALSE),"") -> 0 | EO3: =IFERROR(VLOOKUP($A3,'1878'!$A$3:$I$140,9,FALSE),"") -> 0 | EP3: =IFERROR(VLOOKUP($A3,'1878'!$A$3:$J$140,10,FALSE),"") -> 849.87 | EQ3: =IFERROR(VLOOKUP($A3,'1879'!$A$3:$B$140,2,FALSE),"") -> 954 | ER3: =IFERROR(VLOOKUP($A3,'1879'!$A$3:$C$140,3,FALSE),"") -> 96104.91 | ES3: =IFERROR(VLOOKUP($A3,'1879'!$A$3:$D$140,4,FALSE),"") -> 159 | ET3: =IFERROR(VLOOKUP($A3,'1879'!$A$3:$E$140,5,FALSE),"") -> 16666.26 | EU3: =IFERROR(VLOOKUP($A3,'1879'!$A$3:$F$140,6,FALSE),"") -> 0 | EV3: =IFERROR(VLOOKUP($A3,'1879'!$A$3:$G$140,7,FALSE),"") -> 0 | EW3: =IFERROR(VLOOKUP($A3,'1879'!$A$3:$H$140,8,FALSE),"") -> 0 | EX3: =IFERROR(VLOOKUP($A3,'1879'!$A$3:$I$140,9,FALSE),"") -> 0 | EY3: =IFERROR(VLOOKUP($A3,'1879'!$A$3:$J$140,10,FALSE),"") -> 100 | EZ3: =IFERROR(VLOOKUP($A3,'1880'!$A$3:$B$140,2,FALSE),"") -> 1377 | FA3: =IFERROR(VLOOKUP($A3,'1880'!$A$3:$C$140,3,FALSE),"") -> 144034.36 | FB3: =IFERROR(VLOOKUP($A3,'1880'!$A$3:$D$140,4,FALSE),"") -> 263 | FC3: =IFERROR(VLOOKUP($A3,'1880'!$A$3:$E$140,5,FALSE),"") -> 28891.06 | FD3: =IFERROR(VLOOKUP($A3,'1880'!$A$3:$F$140,6,FALSE),"") -> 0 | FE3: =IFERROR(VLOOKUP($A3,'1880'!$A$3:$G$140,7,FALSE),"") -> 0 | FF3: =IFERROR(VLOOKUP($A3,'1880'!$A$3:$H$140,8,FALSE),"") -> 0 | FG3: =IFERROR(VLOOKUP($A3,'1880'!$A$3:$I$140,9,FALSE),"") -> 0 | FH3: =IFERROR(VLOOKUP($A3,'1880'!$A$3:$J$140,10,FALSE),"") -> 0 | FI3: =IFERROR(VLOOKUP($A3,'1881'!$A$3:$B$140,2,FALSE),"") -> 1159 | FJ3: =IFERROR(VLOOKUP($A3,'1881'!$A$3:$C$140,3,FALSE),"") -> 119444.59 | FK3: =IFERROR(VLOOKUP($A3,'1881'!$A$3:$D$140,4,FALSE),"") -> 333 | FL3: =IFERROR(VLOOKUP($A3,'1881'!$A$3:$E$140,5,FALSE),"") -> 33226.63 | FM3: =IFERROR(VLOOKUP($A3,'1881'!$A$3:$F$140,6,FALSE),"") -> 0 | FN3: =IFERROR(VLOOKUP($A3,'1881'!$A$3:$G$140,7,FALSE),"") -> 0 | FO3: =IFERROR(VLOOKUP($A3,'1881'!$A$3:$H$140,8,FALSE),"") -> 32 | FP3: =IFERROR(VLOOKUP($A3,'1881'!$A$3:$I$140,9,FALSE),"") -> 0 | FQ3: =IFERROR(VLOOKUP($A3,'1881'!$A$3:$J$140,10,FALSE),"") -> 0 | FR3: =IFERROR(VLOOKUP($A3,'1882'!$A$3:$B$140,2,FALSE),"") -> 920 | FS3: =IFERROR(VLOOKUP($A3,'1882'!$A$3:$C$140,3,FALSE),"") -> 104433.75 | FT3: =IFERROR(VLOOKUP($A3,'1882'!$A$3:$D$140,4,FALSE),"") -> 379 | FU3: =IFERROR(VLOOKUP($A3,'1882'!$A$3:$E$140,5,FALSE),"") -> 43153.33 | FV3: =IFERROR(VLOOKUP($A3,'1882'!$A$3:$F$140,6,FALSE),"") -> 5 | FW3: =IFERROR(VLOOKUP($A3,'1882'!$A$3:$G$140,7,FALSE),"") -> 439.82 | FX3: =IFERROR(VLOOKUP($A3,'1882'!$A$3:$H$140,8,FALSE),"") -> 12 | FY3: =IFERROR(VLOOKUP($A3,'1882'!$A$3:$I$140,9,FALSE),"") -> 1282.47 | FZ3: =IFERROR(VLOOKUP($A3,'1882'!$A$3:$J$140,10,FALSE),"") -> 0 | GA3: =IFERROR(VLOOKUP($A3,'1883'!$A$3:$B$140,2,FALSE),"") -> 1033 | GB3: =IFERROR(VLOOKUP($A3,'1883'!$A$3:$C$140,3,FALSE),"") -> 127488.61 | GC3: =IFERROR(VLOOKUP($A3,'1883'!$A$3:$D$140,4,FALSE),"") -> 531 | GD3: =IFERROR(VLOOKUP($A3,'1883'!$A$3:$E$140,5,FALSE),"") -> 58732.67 | GE3: =IFERROR(VLOOKUP($A3,'1883'!$A$3:$F$140,6,FALSE),"") -> 14 | GF3: =IFERROR(VLOOKUP($A3,'1883'!$A$3:$G$140,7,FALSE),"") -> 1253.33 | GG3: =IFERROR(VLOOKUP($A3,'1883'!$A$3:$H$140,8,FALSE),"") -> 35 | GH3: =IFERROR(VLOOKUP($A3,'1883'!$A$3:$I$140,9,FALSE),"") -> 3290.44 | GI3: =IFERROR(VLOOKUP($A3,'1883'!$A$3:$J$140,10,FALSE),"") -> 0 | GJ3: =IFERROR(VLOOKUP($A3,'1884'!$A$3:$B$140,2,FALSE),"") -> 881 | GK3: =IFERROR(VLOOKUP($A3,'1884'!$A$3:$C$140,3,FALSE),"") -> 101201.59 | GL3: =IFERROR(VLOOKUP($A3,'1884'!$A$3:$D$140,4,FALSE),"") -> 640 | GM3: =IFERROR(VLOOKUP($A3,'1884'!$A$3:$E$140,5,FALSE),"") -> 69106.09 | GN3: =IFERROR(VLOOKUP($A3,'1884'!$A$3:$F$140,6,FALSE),"") -> 29 | GO3: =IFERROR(VLOOKUP($A3,'1884'!$A$3:$G$140,7,FALSE),"") -> 3278.66 | GP3: =IFERROR(VLOOKUP($A3,'1884'!$A$3:$H$140,8,FALSE),"") -> 66 | GQ3: =IFERROR(VLOOKUP($A3,'1884'!$A$3:$I$140,9,FALSE),"") -> 5874.8 | GR3: =IFERROR(VLOOKUP($A3,'1884'!$A$3:$J$140,10,FALSE),"") -> 0 | GS3: =IFERROR(VLOOKUP($A3,'1885'!$A$3:$B$140,2,FALSE),"") -> 349 | GT3: =IFERROR(VLOOKUP($A3,'1885'!$A$3:$C$140,3,FALSE),"") -> 36650.11 | GU3: =IFERROR(VLOOKUP($A3,'1885'!$A$3:$D$140,4,FALSE),"") -> 630 | GV3: =IFERROR(VLOOKUP($A3,'1885'!$A$3:$E$140,5,FALSE),"") -> 69546.7 | GW3: =IFERROR(VLOOKUP($A3,'1885'!$A$3:$F$140,6,FALSE),"") -> 8 | GX3: =IFERROR(VLOOKUP($A3,'1885'!$A$3:$G$140,7,FALSE),"") -> 576.86 | GY3: =IFERROR(VLOOKUP($A3,'1885'!$A$3:$H$140,8,FALSE),"") -> 12 | GZ3: =IFERROR(VLOOKUP($A3,'1885'!$A$3:$I$140,9,FALSE),"") -> 790.91 | HA3: =IFERROR(VLOOKUP($A3,'1885'!$A$3:$J$140,10,FALSE),"") -> 0 | HB3: =IFERROR(VLOOKUP($A3,'1886'!$A$3:$B$140,2,FALSE),"") -> 403 | HC3: =IFERROR(VLOOKUP($A3,'1886'!$A$3:$C$140,3,FALSE),"") -> 43733.68 | HD3: =IFERROR(VLOOKUP($A3,'1886'!$A$3:$D$140,4,FALSE),"") -> 614 | HE3: =IFERROR(VLOOKUP($A3,'1886'!$A$3:$E$140,5,FALSE),"") -> 68359.89 | HF3: =IFERROR(VLOOKUP($A3,'1886'!$A$3:$F$140,6,FALSE),"") -> 24 | HG3: =IFERROR(VLOOKUP($A3,'1886'!$A$3:$G$140,7,FALSE),"") -> 2201.19 | HH3: =IFERROR(VLOOKUP($A3,'1886'!$A$3:$H$140,8,FALSE),"") -> 11 | HI3: =IFERROR(VLOOKUP($A3,'1886'!$A$3:$I$140,9,FALSE),"") -> 956.63 | HJ3: =IFERROR(VLOOKUP($A3,'1886'!$A$3:$J$140,10,FALSE),"") -> 0 | HK3: =IFERROR(VLOOKUP($A3,'1887'!$A$3:$B$140,2,FALSE),"") -> 1018 | HL3: =IFERROR(VLOOKUP($A3,'1887'!$A$3:$C$140,3,FALSE),"") -> 131078.79 | HM3: =IFERROR(VLOOKUP($A3,'1887'!$A$3:$D$140,4,FALSE),"") -> 636 | HN3: =IFERROR(VLOOKUP($A3,'1887'!$A$3:$E$140,5,FALSE),"") -> 72618.06 | HO3: =IFERROR(VLOOKUP($A3,'1887'!$A$3:$F$140,6,FALSE),"") -> 10 | HP3: =IFERROR(VLOOKUP($A3,'1887'!$A$3:$G$140,7,FALSE),"") -> 1031.05 | HQ3: =IFERROR(VLOOKUP($A3,'1887'!$A$3:$H$140,8,FALSE),"") -> 45 | HR3: =IFERROR(VLOOKUP($A3,'1887'!$A$3:$I$140,9,FALSE),"") -> 4008.15 | HS3: =IFERROR(VLOOKUP($A3,'1887'!$A$3:$J$140,10,FALSE),"") -> 0 | HT3: =IFERROR(VLOOKUP($A3,'1888'!$A$3:$B$140,2,FALSE),"") -> 1302 | HU3: =IFERROR(VLOOKUP($A3,'1888'!$A$3:$C$140,3,FALSE),"") -> 160692.52 | HV3: =IFERROR(VLOOKUP($A3,'1888'!$A$3:$D$140,4,FALSE),"") -> 662 | HW3: =IFERROR(VLOOKUP($A3,'1888'!$A$3:$E$140,5,FALSE),"") -> 79016.08 | HX3: =IFERROR(VLOOKUP($A3,'1888'!$A$3:$F$140,6,FALSE),"") -> 58 | HY3: =IFERROR(VLOOKUP($A3,'1888'!$A$3:$G$140,7,FALSE),"") -> 7032.58 | HZ3: =IFERROR(VLOOKUP($A3,'1888'!$A$3:$H$140,8,FALSE),"") -> 19 | IA3: =IFERROR(VLOOKUP($A3,'1888'!$A$3:$I$140,9,FALSE),"") -> 1361.64 | IB3: =IFERROR(VLOOKUP($A3,'1888'!$A$3:$J$140,10,FALSE),"") -> 0 | IC3: =IFERROR(VLOOKUP($A3,'1889'!$A$3:$B$140,2,FALSE),"") -> 853 | ID3: =IFERROR(VLOOKUP($A3,'1889'!$A$3:$C$140,3,FALSE),"") -> 102466.19 | IE3: =IFERROR(VLOOKUP($A3,'1889'!$A$3:$D$140,4,FALSE),"") -> 591 | IF3: =IFERROR(VLOOKUP($A3,'1889'!$A$3:$E$140,5,FALSE),"") -> 75678.34 | IG3: =IFERROR(VLOOKUP($A3,'1889'!$A$3:$F$140,6,FALSE),"") -> 65 | IH3: =IFERROR(VLOOKUP($A3,'1889'!$A$3:$G$140,7,FALSE),"") -> 8000.09 | II3: =IFERROR(VLOOKUP($A3,'1889'!$A$3:$H$140,8,FALSE),"") -> 1 | IJ3: =IFERROR(VLOOKUP($A3,'1889'!$A$3:$I$140,9,FALSE),"") -> 119.5 | IK3: =IFERROR(VLOOKUP($A3,'1889'!$A$3:$J$140,10,FALSE),"") -> 0 | IL3: =IFERROR(VLOOKUP($A3,'1890'!$A$3:$B$140,2,FALSE),"") -> 1183 | IM3: =IFERROR(VLOOKUP($A3,'1890'!$A$3:$C$140,3,FALSE),"") -> 134516.4 | IN3: =IFERROR(VLOOKUP($A3,'1890'!$A$3:$D$140,4,FALSE),"") -> 570 | IO3: =IFERROR(VLOOKUP($A3,'1890'!$A$3:$E$140,5,FALSE),"") -> 65351.7 | IP3: =IFERROR(VLOOKUP($A3,'1890'!$A$3:$F$140,6,FALSE),"") -> 54 | IQ3: =IFERROR(VLOOKUP($A3,'1890'!$A$3:$G$140,7,FALSE),"") -> 6617.41 | IR3: =IFERROR(VLOOKUP($A3,'1890'!$A$3:$H$140,8,FALSE),"") -> 6 | IS3: =IFERROR(VLOOKUP($A3,'1890'!$A$3:$I$140,9,FALSE),"") -> 520.47 | IT3: =IFERROR(VLOOKUP($A3,'1890'!$A$3:$J$140,10,FALSE),"") -> 0 | IU3: =IFERROR(VLOOKUP($A3,'1891'!$A$3:$B$140,2,FALSE),"") -> 1681 | IV3: =IFERROR(VLOOKUP($A3,'1891'!$A$3:$C$140,3,FALSE),"") -> 181756.22 | IW3: =IFERROR(VLOOKUP($A3,'1891'!$A$3:$D$140,4,FALSE),"") -> 554 | IX3: =IFERROR(VLOOKUP($A3,'1891'!$A$3:$E$140,5,FALSE),"") -> 62417.74 | IY3: =IFERROR(VLOOKUP($A3,'1891'!$A$3:$F$140,6,FALSE),"") -> 58 | IZ3: =IFERROR(VLOOKUP($A3,'1891'!$A$3:$G$140,7,FALSE),"") -> 5995.26 | JA3: =IFERROR(VLOOKUP($A3,'1891'!$A$3:$H$140,8,FALSE),"") -> 4 | JB3: =IFERROR(VLOOKUP($A3,'1891'!$A$3:$I$140,9,FALSE),"") -> 200.2 | JC3: =IFERROR(VLOOKUP($A3,'1891'!$A$3:$J$140,10,FALSE),"") -> 0 | JD3: =IFERROR(VLOOKUP($A3,'1892'!$A$3:$B$140,2,FALSE),"") -> 888 | JE3: =IFERROR(VLOOKUP($A3,'1892'!$A$3:$C$140,3,FALSE),"") -> 96874.62 | JF3: =IFERROR(VLOOKUP($A3,'1892'!$A$3:$D$140,4,FALSE),"") -> 486 | JG3: =IFERROR(VLOOKUP($A3,'1892'!$A$3:$E$140,5,FALSE),"") -> 55279.07 | JH3: =IFERROR(VLOOKUP($A3,'1892'!$A$3:$F$140,6,FALSE),"") -> 34 | JI3: =IFERROR(VLOOKUP($A3,'1892'!$A$3:$G$140,7,FALSE),"") -> 2627.58 | JJ3: =IFERROR(VLOOKUP($A3,'1892'!$A$3:$H$140,8,FALSE),"") -> 3 | JK3: =IFERROR(VLOOKUP($A3,'1892'!$A$3:$I$140,9,FALSE),"") -> 200.56 | JL3: =IFERROR(VLOOKUP($A3,'1892'!$A$3:$J$140,10,FALSE),"") -> 0 | JM3: =IFERROR(VLOOKUP($A3,'1893'!$A$3:$B$140,2,FALSE),"") -> 540 | JN3: =IFERROR(VLOOKUP($A3,'1893'!$A$3:$C$140,3,FALSE),"") -> 58839.17 | JO3: =IFERROR(VLOOKUP($A3,'1893'!$A$3:$D$140,4,FALSE),"") -> 722 | JP3: =IFERROR(VLOOKUP($A3,'1893'!$A$3:$E$140,5,FALSE),"") -> 93156.17 | JQ3: =IFERROR(VLOOKUP($A3,'1893'!$A$3:$F$140,6,FALSE),"") -> 11 | JR3: =IFERROR(VLOOKUP($A3,'1893'!$A$3:$G$140,7,FALSE),"") -> 919 | JS3: =IFERROR(VLOOKUP($A3,'1893'!$A$3:$H$140,8,FALSE),"") -> 0 | JT3: =IFERROR(VLOOKUP($A3,'1893'!$A$3:$I$140,9,FALSE),"") -> 0 | JU3: =IFERROR(VLOOKUP($A3,'1893'!$A$3:$J$140,10,FALSE),"") -> 0 | JV3: =IFERROR(VLOOKUP($A3,'1894'!$A$3:$B$140,2,FALSE),"") -> 449 | JW3: =IFERROR(VLOOKUP($A3,'1894'!$A$3:$C$140,3,FALSE),"") -> 47738.46 | JX3: =IFERROR(VLOOKUP($A3,'1894'!$A$3:$D$140,4,FALSE),"") -> 634 | JY3: =IFERROR(VLOOKUP($A3,'1894'!$A$3:$E$140,5,FALSE),"") -> 80562.46 | JZ3: =IFERROR(VLOOKUP($A3,'1894'!$A$3:$F$140,6,FALSE),"") -> 9 | KA3: =IFERROR(VLOOKUP($A3,'1894'!$A$3:$G$140,7,FALSE),"") -> 964.82 | KB3: =IFERROR(VLOOKUP($A3,'1894'!$A$3:$H$140,8,FALSE),"") -> 0 | KC3: =IFERROR(VLOOKUP($A3,'1894'!$A$3:$I$140,9,FALSE),"") -> 0 | KD3: =IFERROR(VLOOKUP($A3,'1894'!$A$3:$J$140,10,FALSE),"") -> 0 | KE3: =IFERROR(VLOOKUP($A3,'1895'!$A$3:$B$140,2,FALSE),"") -> 276 | KF3: =IFERROR(VLOOKUP($A3,'1895'!$A$3:$C$140,3,FALSE),"") -> 28760.16 | KG3: =IFERROR(VLOOKUP($A3,'1895'!$A$3:$D$140,4,FALSE),"") -> 496 | KH3: =IFERROR(VLOOKUP($A3,'1895'!$A$3:$E$140,5,FALSE),"") -> 60539.55 | KI3: =IFERROR(VLOOKUP($A3,'1895'!$A$3:$F$140,6,FALSE),"") -> 9 | KJ3: =IFERROR(VLOOKUP($A3,'1895'!$A$3:$G$140,7,FALSE),"") -> 557.83 | KK3: =IFERROR(VLOOKUP($A3,'1895'!$A$3:$H$140,8,FALSE),"") -> 0 | KL3: =IFERROR(VLOOKUP($A3,'1895'!$A$3:$I$140,9,FALSE),"") -> 0 | KM3: =IFERROR(VLOOKUP($A3,'1895'!$A$3:$J$140,10,FALSE),"") -> 0 | KN3: =IFERROR(VLOOKUP($A3,'1896'!$A$3:$B$140,2,FALSE),"") -> 475 | KO3: =IFERROR(VLOOKUP($A3,'1896'!$A$3:$C$140,3,FALSE),"") -> 48567.3 | KP3: =IFERROR(VLOOKUP($A3,'1896'!$A$3:$D$140,4,FALSE),"") -> 666 | KQ3: =IFERROR(VLOOKUP($A3,'1896'!$A$3:$E$140,5,FALSE),"") -> 75829.25 | KR3: =IFERROR(VLOOKUP($A3,'1896'!$A$3:$F$140,6,FALSE),"") -> 9 | KS3: =IFERROR(VLOOKUP($A3,'1896'!$A$3:$G$140,7,FALSE),"") -> 890.58 | KT3: =IFERROR(VLOOKUP($A3,'1896'!$A$3:$H$140,8,FALSE),"") -> 0 | KU3: =IFERROR(VLOOKUP($A3,'1896'!$A$3:$I$140,9,FALSE),"") -> 0 | KV3: =IFERROR(VLOOKUP($A3,'1896'!$A$3:$J$140,10,FALSE),"") -> 0 | KW3: =IFERROR(VLOOKUP($A3,'1897'!$A$3:$B$140,2,FALSE),"") -> 466 | KX3: =IFERROR(VLOOKUP($A3,'1897'!$A$3:$C$140,3,FALSE),"") -> 48423.67 | KY3: =IFERROR(VLOOKUP($A3,'1897'!$A$3:$D$140,4,FALSE),"") -> 574 | KZ3: =IFERROR(VLOOKUP($A3,'1897'!$A$3:$E$140,5,FALSE),"") -> 66700.28 | LA3: =IFERROR(VLOOKUP($A3,'1897'!$A$3:$F$140,6,FALSE),"") -> 3 | LB3: =IFERROR(VLOOKUP($A3,'1897'!$A$3:$G$140,7,FALSE),"") -> 360.18 | LC3: =IFERROR(VLOOKUP($A3,'1897'!$A$3:$H$140,8,FALSE),"") -> 0 | LD3: =IFERROR(VLOOKUP($A3,'1897'!$A$3:$I$140,9,FALSE),"") -> 0 | LE3: =IFERROR(VLOOKUP($A3,'1897'!$A$3:$J$140,10,FALSE),"") -> 0 | LF3: =IFERROR(VLOOKUP($A3,'1898'!$A$3:$B$140,2,FALSE),"") -> 530 | LG3: =IFERROR(VLOOKUP($A3,'1898'!$A$3:$C$140,3,FALSE),"") -> 56870.89 | LH3: =IFERROR(VLOOKUP($A3,'1898'!$A$3:$D$140,4,FALSE),"") -> 524 | LI3: =IFERROR(VLOOKUP($A3,'1898'!$A$3:$E$140,5,FALSE),"") -> 59838.09 | LJ3: =IFERROR(VLOOKUP($A3,'1898'!$A$3:$F$140,6,FALSE),"") -> 4 | LK3: =IFERROR(VLOOKUP($A3,'1898'!$A$3:$G$140,7,FALSE),"") -> 240.71 | LL3: =IFERROR(VLOOKUP($A3,'1898'!$A$3:$H$140,8,FALSE),"") -> 0 | LM3: =IFERROR(VLOOKUP($A3,'1898'!$A$3:$I$140,9,FALSE),"") -> 0 | LN3: =IFERROR(VLOOKUP($A3,'1898'!$A$3:$J$140,10,FALSE),"") -> 0 | LO3: =IFERROR(VLOOKUP($A3,'1899'!$A$3:$B$140,2,FALSE),"") -> 668 | LP3: =IFERROR(VLOOKUP($A3,'1899'!$A$3:$C$140,3,FALSE),"") -> 69404.07 | LQ3: =IFERROR(VLOOKUP($A3,'1899'!$A$3:$D$140,4,FALSE),"") -> 491 | LR3: =IFERROR(VLOOKUP($A3,'1899'!$A$3:$E$140,5,FALSE),"") -> 54742.31 | LS3: =IFERROR(VLOOKUP($A3,'1899'!$A$3:$F$140,6,FALSE),"") -> 6 | LT3: =IFERROR(VLOOKUP($A3,'1899'!$A$3:$G$140,7,FALSE),"") -> 484.9 | LU3: =IFERROR(VLOOKUP($A3,'1899'!$A$3:$H$140,8,FALSE),"") -> 0 | LV3: =IFERROR(VLOOKUP($A3,'1899'!$A$3:$I$140,9,FALSE),"") -> 0 | LW3: =IFERROR(VLOOKUP($A3,'1899'!$A$3:$J$140,10,FALSE),"") -> 0 | LX3: =IFERROR(VLOOKUP($A3,'1900'!$A$3:$B$140,2,FALSE),"") -> 664 | LY3: =IFERROR(VLOOKUP($A3,'1900'!$A$3:$C$140,3,FALSE),"") -> 63891.95 | LZ3: =IFERROR(VLOOKUP($A3,'1900'!$A$3:$D$140,4,FALSE),"") -> 352 | MA3: =IFERROR(VLOOKUP($A3,'1900'!$A$3:$E$140,5,FALSE),"") -> 38482.32 | MB3: =IFERROR(VLOOKUP($A3,'1900'!$A$3:$F$140,6,FALSE),"") -> 11 | MC3: =IFERROR(VLOOKUP($A3,'1900'!$A$3:$G$140,7,FALSE),"") -> 1035.35 | MD3: =IFERROR(VLOOKUP($A3,'1900'!$A$3:$H$140,8,FALSE),"") -> 0 | ME3: =IFERROR(VLOOKUP($A3,'1900'!$A$3:$I$140,9,FALSE),"") -> 0 | MF3: =IFERROR(VLOOKUP($A3,'1900'!$A$3:$J$140,10,FALSE),"") -> 0 | MG3: =IFERROR(VLOOKUP($A3,'1901'!$A$3:$B$140,2,FALSE),"") -> 441 | MH3: =IFERROR(VLOOKUP($A3,'1901'!$A$3:$C$140,3,FALSE),"") -> 42725.45 | MI3: =IFERROR(VLOOKUP($A3,'1901'!$A$3:$D$140,4,FALSE),"") -> 316 | MJ3: =IFERROR(VLOOKUP($A3,'1901'!$A$3:$E$140,5,FALSE),"") -> 36167.37 | MK3: =IFERROR(VLOOKUP($A3,'1901'!$A$3:$F$140,6,FALSE),"") -> 7 | ML3: =IFERROR(VLOOKUP($A3,'1901'!$A$3:$G$140,7,FALSE),"") -> 795.88 | MM3: =IFERROR(VLOOKUP($A3,'1901'!$A$3:$H$140,8,FALSE),"") -> 0 | MN3: =IFERROR(VLOOKUP($A3,'1901'!$A$3:$I$140,9,FALSE),"") -> 0 | MO3: =IFERROR(VLOOKUP($A3,'1901'!$A$3:$J$140,10,FALSE),"") -> 0 | MP3: =IFERROR(VLOOKUP($A3,'1902'!$A$3:$B$140,2,FALSE),"") -> 347 | MQ3: =IFERROR(VLOOKUP($A3,'1902'!$A$3:$C$140,3,FALSE),"") -> 33661.32 | MR3: =IFERROR(VLOOKUP($A3,'1902'!$A$3:$D$140,4,FALSE),"") -> 284 | MS3: =IFERROR(VLOOKUP($A3,'1902'!$A$3:$E$140,5,FALSE),"") -> 31616.94 | MT3: =IFERROR(VLOOKUP($A3,'1902'!$A$3:$F$140,6,FALSE),"") -> 18 | MU3: =IFERROR(VLOOKUP($A3,'1902'!$A$3:$G$140,7,FALSE),"") -> 1905.12 | MV3: =IFERROR(VLOOKUP($A3,'1902'!$A$3:$H$140,8,FALSE),"") -> 0 | MW3: =IFERROR(VLOOKUP($A3,'1902'!$A$3:$I$140,9,FALSE),"") -> 0 | MX3: =IFERROR(VLOOKUP($A3,'1902'!$A$3:$J$140,10,FALSE),"") -> 0 | MY3: =IFERROR(VLOOKUP($A3,'1903'!$A$3:$B$140,2,FALSE),"") -> 556 | MZ3: =IFERROR(VLOOKUP($A3,'1903'!$A$3:$C$140,3,FALSE),"") -> 56815.82 | NA3: =IFERROR(VLOOKUP($A3,'1903'!$A$3:$D$140,4,FALSE),"") -> 343 | NB3: =IFERROR(VLOOKUP($A3,'1903'!$A$3:$E$140,5,FALSE),"") -> 37099.89 | NC3: =IFERROR(VLOOKUP($A3,'1903'!$A$3:$F$140,6,FALSE),"") -> 17 | ND3: =IFERROR(VLOOKUP($A3,'1903'!$A$3:$G$140,7,FALSE),"") -> 1754.38 | NE3: =IFERROR(VLOOKUP($A3,'1903'!$A$3:$H$140,8,FALSE),"") -> 0 | NF3: =IFERROR(VLOOKUP($A3,'1903'!$A$3:$I$140,9,FALSE),"") -> 0 | NG3: =IFERROR(VLOOKUP($A3,'1903'!$A$3:$J$140,10,FALSE),"") -> 0 | NH3: =IFERROR(VLOOKUP($A3,'1904'!$A$3:$B$140,2,FALSE),"") -> 359 | NI3: =IFERROR(VLOOKUP($A3,'1904'!$A$3:$C$140,3,FALSE),"") -> 35818.61 | NJ3: =IFERROR(VLOOKUP($A3,'1904'!$A$3:$D$140,4,FALSE),"") -> 372 | NK3: =IFERROR(VLOOKUP($A3,'1904'!$A$3:$E$140,5,FALSE),"") -> 39826.72 | NL3: =IFERROR(VLOOKUP($A3,'1904'!$A$3:$F$140,6,FALSE),"") -> 22 | NM3: =IFERROR(VLOOKUP($A3,'1904'!$A$3:$G$140,7,FALSE),"") -> 1752.87 | NN3: =IFERROR(VLOOKUP($A3,'1904'!$A$3:$H$140,8,FALSE),"") -> 0 | NO3: =IFERROR(VLOOKUP($A3,'1904'!$A$3:$I$140,9,FALSE),"") -> 0 | NP3: =IFERROR(VLOOKUP($A3,'1904'!$A$3:$J$140,10,FALSE),"") -> 0 | NQ3: =IFERROR(VLOOKUP($A3,'1905'!$A$3:$B$140,2,FALSE),"") -> 266 | NR3: =IFERROR(VLOOKUP($A3,'1905'!$A$3:$C$140,3,FALSE),"") -> 27016.78 | NS3: =IFERROR(VLOOKUP($A3,'1905'!$A$3:$D$140,4,FALSE),"") -> 248 | NT3: =IFERROR(VLOOKUP($A3,'1905'!$A$3:$E$140,5,FALSE),"") -> 26902.81 | NU3: =IFERROR(VLOOKUP($A3,'1905'!$A$3:$F$140,6,FALSE),"") -> 15 | NV3: =IFERROR(VLOOKUP($A3,'1905'!$A$3:$G$140,7,FALSE),"") -> 1283.54 | NW3: =IFERROR(VLOOKUP($A3,'1905'!$A$3:$H$140,8,FALSE),"") -> 0 | NX3: =IFERROR(VLOOKUP($A3,'1905'!$A$3:$I$140,9,FALSE),"") -> 0 | NY3: =IFERROR(VLOOKUP($A3,'1905'!$A$3:$J$140,10,FALSE),"") -> 0 | NZ3: =IFERROR(VLOOKUP($A3,'1906'!$A$3:$B$140,2,FALSE),"") | OA3: =IFERROR(VLOOKUP($A3,'1906'!$A$3:$C$140,3,FALSE),"") | OB3: =IFERROR(VLOOKUP($A3,'1906'!$A$3:$D$140,4,FALSE),"") | OC3: =IFERROR(VLOOKUP($A3,'1906'!$A$3:$E$140,5,FALSE),"") | OD3: =IFERROR(VLOOKUP($A3,'1906'!$A$3:$F$140,6,FALSE),"") | OE3: =IFERROR(VLOOKUP($A3,'1906'!$A$3:$G$140,7,FALSE),"") | OF3: =IFERROR(VLOOKUP($A3,'1906'!$A$3:$H$140,8,FALSE),"") | OG3: =IFERROR(VLOOKUP($A3,'1906'!$A$3:$I$140,9,FALSE),"") | OH3: =IFERROR(VLOOKUP($A3,'1906'!$A$3:$J$140,10,FALSE),"") | OI3: =IFERROR(VLOOKUP($A3,'1907'!$A$3:$B$140,2,FALSE),"") | OJ3: =IFERROR(VLOOKUP($A3,'1907'!$A$3:$C$140,3,FALSE),"") | OK3: =IFERROR(VLOOKUP($A3,'1907'!$A$3:$D$140,4,FALSE),"") | OL3: =IFERROR(VLOOKUP($A3,'1907'!$A$3:$E$140,5,FALSE),"") | OM3: =IFERROR(VLOOKUP($A3,'1907'!$A$3:$F$140,6,FALSE),"") | ON3: =IFERROR(VLOOKUP($A3,'1907'!$A$3:$G$140,7,FALSE),"") | OO3: =IFERROR(VLOOKUP($A3,'1907'!$A$3:$H$140,8,FALSE),"") | OP3: =IFERROR(VLOOKUP($A3,'1907'!$A$3:$I$140,9,FALSE),"") | OQ3: =IFERROR(VLOOKUP($A3,'1907'!$A$3:$J$140,10,FALSE),"") | OR3: =IFERROR(VLOOKUP($A3,'1908'!$A$3:$B$140,2,FALSE),"") | OS3: =IFERROR(VLOOKUP($A3,'1908'!$A$3:$C$140,3,FALSE),"") | OT3: =IFERROR(VLOOKUP($A3,'1908'!$A$3:$D$140,4,FALSE),"") | OU3: =IFERROR(VLOOKUP($A3,'1908'!$A$3:$E$140,5,FALSE),"") | OV3: =IFERROR(VLOOKUP($A3,'1908'!$A$3:$F$140,6,FALSE),"") | OW3: =IFERROR(VLOOKUP($A3,'1908'!$A$3:$G$140,7,FALSE),"") | OX3: =IFERROR(VLOOKUP($A3,'1908'!$A$3:$H$140,8,FALSE),"") | OY3: =IFERROR(VLOOKUP($A3,'1908'!$A$3:$I$140,9,FALSE),"") | OZ3: =IFERROR(VLOOKUP($A3,'1908'!$A$3:$J$140,10,FALSE),"") | PA3: =IFERROR(VLOOKUP($A3,'1909'!$A$3:$B$140,2,FALSE),"") | PB3: =IFERROR(VLOOKUP($A3,'1909'!$A$3:$C$140,3,FALSE),"") | PC3: =IFERROR(VLOOKUP($A3,'1909'!$A$3:$D$140,4,FALSE),"") | PD3: =IFERROR(VLOOKUP($A3,'1909'!$A$3:$E$140,5,FALSE),"") | PE3: =IFERROR(VLOOKUP($A3,'1909'!$A$3:$F$140,6,FALSE),"") | PF3: =IFERROR(VLOOKUP($A3,'1909'!$A$3:$G$140,7,FALSE),"") | PG3: =IFERROR(VLOOKUP($A3,'1909'!$A$3:$H$140,8,FALSE),"") | PH3: =IFERROR(VLOOKUP($A3,'1909'!$A$3:$I$140,9,FALSE),"") | PI3: =IFERROR(VLOOKUP($A3,'1909'!$A$3:$J$140,10,FALSE),"") | PJ3: =IFERROR(VLOOKUP($A3,'1910'!$A$3:$B$140,2,FALSE),"") | PK3: =IFERROR(VLOOKUP($A3,'1910'!$A$3:$C$140,3,FALSE),"") | PL3: =IFERROR(VLOOKUP($A3,'1910'!$A$3:$D$140,4,FALSE),"") | PM3: =IFERROR(VLOOKUP($A3,'1910'!$A$3:$E$140,5,FALSE),"") | PN3: =IFERROR(VLOOKUP($A3,'1910'!$A$3:$F$140,6,FALSE),"") | PO3: =IFERROR(VLOOKUP($A3,'1910'!$A$3:$G$140,7,FALSE),"") | PP3: =IFERROR(VLOOKUP($A3,'1910'!$A$3:$H$140,8,FALSE),"") | PQ3: =IFERROR(VLOOKUP($A3,'1910'!$A$3:$I$140,9,FALSE),"") | PR3: =IFERROR(VLOOKUP($A3,'1910'!$A$3:$J$140,10,FALSE),"") | PS3: =IFERROR(VLOOKUP($A3,'1911'!$A$3:$B$140,2,FALSE),"") | PT3: =IFERROR(VLOOKUP($A3,'1911'!$A$3:$C$140,3,FALSE),"") | PU3: =IFERROR(VLOOKUP($A3,'1911'!$A$3:$D$140,4,FALSE),"") | PV3: =IFERROR(VLOOKUP($A3,'1911'!$A$3:$E$140,5,FALSE),"") | PW3: =IFERROR(VLOOKUP($A3,'1911'!$A$3:$F$140,6,FALSE),"") | PX3: =IFERROR(VLOOKUP($A3,'1911'!$A$3:$G$140,7,FALSE),"") | PY3: =IFERROR(VLOOKUP($A3,'1911'!$A$3:$H$140,8,FALSE),"") | PZ3: =IFERROR(VLOOKUP($A3,'1911'!$A$3:$I$140,9,FALSE),"") | QA3: =IFERROR(VLOOKUP($A3,'1911'!$A$3:$J$140,10,FALSE),"") | QB3: =IFERROR(VLOOKUP($A3,'1912'!$A$3:$B$140,2,FALSE),"") | QC3: =IFERROR(VLOOKUP($A3,'1912'!$A$3:$C$140,3,FALSE),"") | QD3: =IFERROR(VLOOKUP($A3,'1912'!$A$3:$D$140,4,FALSE),"") | QE3: =IFERROR(VLOOKUP($A3,'1912'!$A$3:$E$140,5,FALSE),"") | QF3: =IFERROR(VLOOKUP($A3,'1912'!$A$3:$F$140,6,FALSE),"") | QG3: =IFERROR(VLOOKUP($A3,'1912'!$A$3:$G$140,7,FALSE),"") | QH3: =IFERROR(VLOOKUP($A3,'1912'!$A$3:$H$140,8,FALSE),"") | QI3: =IFERROR(VLOOKUP($A3,'1912'!$A$3:$I$140,9,FALSE),"") | QJ3: =IFERROR(VLOOKUP($A3,'1912'!$A$3:$J$140,10,FALSE),"")
